<?xml version="1.0" ?>
<!-- =================================================================================== -->
<!-- |    This document was autogenerated by xacro from /home/aubo/catkin_aubo/src/aubo_ros_driver/aubo_description/urdf/aubo_i5_robot.urdf.xacro | -->
<!-- |    EDITING THIS FILE BY HAND IS NOT RECOMMENDED                                 | -->
<!-- =================================================================================== -->
<robot name="aubo_i5">
    <gazebo>
        <plugin filename="libgazebo_ros_control.so" name="ros_control">
            <!--robotNamespace>/aubo_robot</robotNamespace-->
            <!--robotSimType>gazebo_ros_control/DefaultRobotHWSim</robotSimType-->
        </plugin>
        <plugin name="gazebo_ros_control">
            <robotNamespace>/</robotNamespace>
        </plugin>
    </gazebo>
    <!--xacro:include filename="$(find your_robot_description)/urdf/materials.xacro" /-->
    <!-- measured from model -->
    <!--property name="shoulder_height" value="0.089159" /-->
    <!--property name="shoulder_offset" value="0.13585" /-->
    <!-- shoulder_offset - elbow_offset + wrist_1_length = 0.10915 -->
    <!--property name="upper_arm_length" value="0.42500" /-->
    <!--property name="elbow_offset" value="0.1197" /-->
    <!-- CAD measured -->
    <!--property name="forearm_length" value="0.39225" /-->
    <!--property name="wrist_1_length" value="0.093" /-->
    <!-- CAD measured -->
    <!--property name="wrist_2_length" value="0.09465" /-->
    <!-- In CAD this distance is 0.930, but in the spec it is 0.09465 -->
    <!--property name="wrist_3_length" value="0.0823" /-->
    <!-- manually measured -->
    <link name="base_link">
        <inertial>
            <origin rpy="0 0 0" xyz="-1.4795E-13 0.0015384 0.020951" />
            <mass value="0.83419" />
            <inertia ixx="0.0014414" ixy="7.8809E-15" ixz="8.5328E-16" iyy="0.0013542" iyz="-1.4364E-05" izz="0.0024659" />
        </inertial>
        <visual>
            <origin rpy="0 0 0" xyz="0 0 0" />
            <geometry>
                <mesh filename="package://aubo_description/meshes/aubo_i5/visual/base_link.DAE" />
            </geometry>
            <material name="">
                <color rgba="1 1 1 1" />
            </material>
        </visual>
        <collision>
            <origin rpy="0 0 0" xyz="0 0 0" />
            <geometry>
                <mesh filename="package://aubo_description/meshes/aubo_i5/collision/base_link.STL" />
            </geometry>
        </collision>
    </link>
    <link name="shoulder_Link">
        <inertial>
            <origin rpy="0 0 0" xyz="3.2508868974735E-07 0.00534955349296065 -0.00883689325611056" />
            <mass value="1.57658348693929" />
            <inertia ixx="0.0040640448663128" ixy="0" ixz="0" iyy="0.00392863238466817" iyz="-0.000160151642851425" izz="0.0030869857349184" />
        </inertial>
        <visual>
            <origin rpy="0 0 0" xyz="0 0 0" />
            <geometry>
                <mesh filename="package://aubo_description/meshes/aubo_i5/visual/shoulder_Link.DAE" />
            </geometry>
            <material name="">
                <color rgba="1 1 1 1" />
            </material>
        </visual>
        <collision>
            <origin rpy="0 0 0" xyz="0 0 0" />
            <geometry>
                <mesh filename="package://aubo_description/meshes/aubo_i5/collision/shoulder_Link.STL" />
            </geometry>
        </collision>
    </link>
    <joint name="shoulder_joint" type="revolute">
        <origin rpy="0 0 3.1416" xyz="0 0 0.122" />
        <parent link="base_link" />
        <child link="shoulder_Link" />
        <axis xyz="0 0 1" />
        <limit effort="150.0" lower="-3.04" upper="3.04" velocity="3.15" />
    </joint>
    <link name="upperArm_Link">
        <inertial>
            <origin rpy="0 0 0" xyz="0.203996646979614 2.01304585036544E-10 0.0127641545395984" />
            <mass value="4.04175782265494" />
            <inertia ixx="0.00965399211106204" ixy="0" ixz="0" iyy="0.144993869035655" iyz="0" izz="0.142607184038966" />
        </inertial>
        <visual>
            <origin rpy="0 0 0" xyz="0 0 0" />
            <geometry>
                <mesh filename="package://aubo_description/meshes/aubo_i5/visual/upperArm_Link.DAE" />
            </geometry>
            <material name="">
                <color rgba="1 1 1 1" />
            </material>
        </visual>
        <collision>
            <origin rpy="0 0 0" xyz="0 0 0" />
            <geometry>
                <mesh filename="package://aubo_description/meshes/aubo_i5/collision/upperArm_Link.STL" />
            </geometry>
        </collision>
    </link>
    <joint name="upperArm_joint" type="revolute">
        <origin rpy="-1.5708 -1.5708 0" xyz="0 0.1215 0" />
        <parent link="shoulder_Link" />
        <child link="upperArm_Link" />
        <axis xyz="0 0 1" />
        <limit effort="150.0" lower="-3.04" upper="3.04" velocity="3.15" />
    </joint>
    <link name="foreArm_Link">
        <inertial>
            <origin rpy="0 0 0" xyz="0.188922115560337 6.78882434739072E-07 0.0981026740461557" />
            <mass value="2.27145669098343" />
            <inertia ixx="0.00214322284946289" ixy="0" ixz="-0.00073120631553383" iyy="0.0443926090878205" iyz="0" izz="0.0441273797128365" />
        </inertial>
        <visual>
            <origin rpy="0 0 0" xyz="0 0 0" />
            <geometry>
                <mesh filename="package://aubo_description/meshes/aubo_i5/visual/foreArm_Link.DAE" />
            </geometry>
            <material name="">
                <color rgba="1 1 1 1" />
            </material>
        </visual>
        <collision>
            <origin rpy="0 0 0" xyz="0 0 0" />
            <geometry>
                <mesh filename="package://aubo_description/meshes/aubo_i5/collision/foreArm_Link.STL" />
            </geometry>
        </collision>
    </link>
    <joint name="foreArm_joint" type="revolute">
        <origin rpy="-3.1416 -5.1632E-18 -5.459E-16" xyz="0.408 0 0" />
        <parent link="upperArm_Link" />
        <child link="foreArm_Link" />
        <axis xyz="0 0 1" />
        <limit effort="150.0" lower="-3.04" upper="3.04" velocity="3.5" />
    </joint>
    <link name="wrist1_Link">
        <inertial>
            <origin rpy="0 0 0" xyz="7.54205137428592E-07 0.0062481254331257 -0.00392367464072373" />
            <mass value="0.500477539188764" />
            <inertia ixx="0.00071194605962081" ixy="0" ixz="0" iyy="0.00040588242872958" iyz="-2.30808694377512E-05" izz="0.000685574004861334" />
        </inertial>
        <visual>
            <origin rpy="0 0 0" xyz="0 0 0" />
            <geometry>
                <mesh filename="package://aubo_description/meshes/aubo_i5/visual/wrist1_Link.DAE" />
            </geometry>
            <material name="">
                <color rgba="1 1 1 1" />
            </material>
        </visual>
        <collision>
            <origin rpy="0 0 0" xyz="0 0 0" />
            <geometry>
                <mesh filename="package://aubo_description/meshes/aubo_i5/collision/wrist1_Link.STL" />
            </geometry>
        </collision>
    </link>
    <joint name="wrist1_joint" type="revolute">
        <origin rpy="3.1416 -1.8323E-15 1.5708" xyz="0.376 0 0" />
        <parent link="foreArm_Link" />
        <child link="wrist1_Link" />
        <axis xyz="0 0 1" />
        <limit effort="28.0" lower="-3.04" upper="3.04" velocity="3.2" />
    </joint>
    <link name="wrist2_Link">
        <inertial>
            <origin rpy="0 0 0" xyz="-7.54207620578635E-07 -0.00624812542617262 -0.00392367464115684" />
            <mass value="0.500477539245988" />
            <inertia ixx="0.00071194605981829" ixy="0" ixz="0" iyy="0.000405882428755442" iyz="2.30808694515886E-05" izz="0.000685574005112107" />
        </inertial>
        <visual>
            <origin rpy="0 0 0" xyz="0 0 0" />
            <geometry>
                <mesh filename="package://aubo_description/meshes/aubo_i5/visual/wrist2_Link.DAE" />
            </geometry>
            <material name="">
                <color rgba="1 1 1 1" />
            </material>
        </visual>
        <collision>
            <origin rpy="0 0 0" xyz="0 0 0" />
            <geometry>
                <mesh filename="package://aubo_description/meshes/aubo_i5/collision/wrist2_Link.STL" />
            </geometry>
        </collision>
    </link>
    <joint name="wrist2_joint" type="revolute">
        <origin rpy="-1.5708 -1.8709E-15 -1.6653E-16" xyz="0 0.1025 0" />
        <parent link="wrist1_Link" />
        <child link="wrist2_Link" />
        <axis xyz="0 0 1" />
        <limit effort="28.0" lower="-3.04" upper="3.04" velocity="3.2" />
    </joint>
    <link name="wrist3_Link">
        <inertial>
            <origin rpy="0 0 0" xyz="3.92048778449938E-10 0.000175788057281467 -0.0213294490706684" />
            <mass value="0.158309554874285" />
            <inertia ixx="7.31376196034769E-05" ixy="0" ixz="0" iyy="7.19528188876563E-05" iyz="0" izz="0.000108772439051422" />
        </inertial>
        <visual>
            <origin rpy="0 0 0" xyz="0 0 0" />
            <geometry>
                <mesh filename="package://aubo_description/meshes/aubo_i5/visual/wrist3_Link.DAE" />
            </geometry>
            <material name="">
                <color rgba="1 1 1 1" />
            </material>
        </visual>
        <collision>
            <origin rpy="0 0 0" xyz="0 0 0" />
            <geometry>
                <mesh filename="package://aubo_description/meshes/aubo_i5/collision/wrist3_Link.STL" />
            </geometry>
        </collision>
    </link>
    <joint name="wrist3_joint" type="revolute">
        <origin rpy="1.5708 0 1.7907E-15" xyz="0 -0.094 0" />
        <parent link="wrist2_Link" />
        <child link="wrist3_Link" />
        <axis xyz="0 0 1" />
        <limit effort="28.0" lower="-3.04" upper="3.04" velocity="3.2" />
    </joint>
    <joint name="ee_fixed_joint" type="fixed">
        <parent link="wrist3_Link" />
        <child link="ee_link" />
        <origin rpy="0.0 0.0 1.5707963267948966" xyz="0.0 0.0 0.0" />
    </joint>
    <link name="ee_link">
        <collision>
            <geometry>
                <box size="0.01 0.01 0.01" />
            </geometry>
            <origin rpy="0 0 0" xyz="-0.01 0 0" />
        </collision>
        <inertial>
            <mass value="0.1" />
            <origin xyz="0 0 0" rpy="0 0 0" />
            <inertia ixx="0.03" iyy="0.03" izz="0.03" ixy="0.0" ixz="0.0" iyz="0.0" />
        </inertial>
    </link>
    <transmission name="shoulder_trans">
        <type>transmission_interface/SimpleTransmission</type>
        <joint name="shoulder_joint">
            <hardwareInterface>hardware_interface/PositionJointInterface</hardwareInterface>
        </joint>
        <actuator name="shoulder_motor">
            <mechanicalReduction>1</mechanicalReduction>
            <hardwareInterface>hardware_interface/EffortJointInterface</hardwareInterface>
        </actuator>
    </transmission>
    <transmission name="foreArm_trans">
        <type>transmission_interface/SimpleTransmission</type>
        <joint name="foreArm_joint">
            <hardwareInterface>hardware_interface/PositionJointInterface</hardwareInterface>
        </joint>
        <actuator name="foreArm_motor">
            <mechanicalReduction>1</mechanicalReduction>
            <hardwareInterface>hardware_interface/EffortJointInterface</hardwareInterface>
        </actuator>
    </transmission>
    <transmission name="upperArm_trans">
        <type>transmission_interface/SimpleTransmission</type>
        <joint name="upperArm_joint">
            <hardwareInterface>hardware_interface/PositionJointInterface</hardwareInterface>
        </joint>
        <actuator name="upperArm_motor">
            <mechanicalReduction>1</mechanicalReduction>
            <hardwareInterface>hardware_interface/EffortJointInterface</hardwareInterface>
        </actuator>
    </transmission>
    <transmission name="wrist1_trans">
        <type>transmission_interface/SimpleTransmission</type>
        <joint name="wrist1_joint">
            <hardwareInterface>hardware_interface/PositionJointInterface</hardwareInterface>
        </joint>
        <actuator name="wrist1_motor">
            <mechanicalReduction>1</mechanicalReduction>
            <hardwareInterface>hardware_interface/EffortJointInterface</hardwareInterface>
        </actuator>
    </transmission>
    <transmission name="wrist2_trans">
        <type>transmission_interface/SimpleTransmission</type>
        <joint name="wrist2_joint">
            <hardwareInterface>hardware_interface/PositionJointInterface</hardwareInterface>
        </joint>
        <actuator name="wrist2_motor">
            <mechanicalReduction>1</mechanicalReduction>
            <hardwareInterface>hardware_interface/EffortJointInterface</hardwareInterface>
        </actuator>
    </transmission>
    <transmission name="wrist3_trans">
        <type>transmission_interface/SimpleTransmission</type>
        <joint name="wrist3_joint">
            <hardwareInterface>hardware_interface/PositionJointInterface</hardwareInterface>
        </joint>
        <actuator name="wrist3_motor">
            <mechanicalReduction>1</mechanicalReduction>
            <hardwareInterface>hardware_interface/EffortJointInterface</hardwareInterface>
        </actuator>
    </transmission>
    <gazebo reference="shoulder_Link">
        <selfCollide>true</selfCollide>
    </gazebo>
    <gazebo reference="upperArm_Link">
        <selfCollide>true</selfCollide>
    </gazebo>
    <gazebo reference="foreArm_Link">
        <selfCollide>true</selfCollide>
    </gazebo>
    <gazebo reference="wrist1_Link">
        <selfCollide>true</selfCollide>
    </gazebo>
    <gazebo reference="wrist2_Link">
        <selfCollide>true</selfCollide>
    </gazebo>
    <gazebo reference="wrist3_Link">
        <selfCollide>true</selfCollide>
    </gazebo>
    <gazebo reference="ee_link">
        <selfCollide>true</selfCollide>
    </gazebo>
    <link name="world" />
    <joint name="world_joint" type="fixed">
        <parent link="world" />
        <child link="base_link" />
        <origin rpy="0.0 0.0 0.0" xyz="0.0 0.0 0.0" />
    </joint>
</robot>

